在Java中，如果一个方法声明了它可能会抛出一个异常（使用`throws`关键字），那么在该方法中抛出异常后，就不需要再使用`return`语句。因为一旦抛出异常，方法的执行就会立即停止，并且控制权会返回到调用者，调用者可以选择捕获并处理这个异常。

但是，如果一个方法没有声明可能会抛出异常，那么在所有的执行路径上，该方法都必须有一个`return`语句。这意味着如果你在一个`try`块中抛出了一个异常，那么你需要在一个`catch`块或者一个`finally`块中有一个`return`语句，或者在方法的最后有一个`return`语句。

以下是一个示例：

```java
public int test() {
    try {
        // 可能会抛出异常的代码
        int result = 10 / 0;
        return result;
    } catch (Exception e) {
        // 处理异常
        return -1;
    } finally {
        // 无论是否发生异常，都会执行
        System.out.println("In finally block");
    }
}
```

在这个例子中，`try`块中的代码会抛出一个`ArithmeticException`，然后控制权会转到`catch`块。在`catch`块中，我们返回-1。如果`try`块中的代码没有抛出异常，那么`try`块中的`return`语句会被执行。无论哪种情况，`finally`块中的代码都会被执行。